<?xml version="1.0"?>
<rss xmlns:dc="http://purl.org/dc/elements/1.1/" version="2.0">
  <channel>
    <title>CKAN: Ticket #1621: UnicodeDecodeError when validating user password</title>
    <link>http://localhost/ticket/1621</link>
    <description>&lt;p&gt;
A test case is currently failing for me on master:
&lt;/p&gt;
&lt;pre class="wiki"&gt;ERROR: ckan.tests.functional.test_user.TestUserController.test_user_create_unicode
----------------------------------------------------------------------
Traceback (most recent call last):
  File "/home/seanh/pyenv/lib/python2.6/site-packages/nose/case.py", line 197, in runTest
    self.test(*self.arg)
  File "/home/seanh/pyenv/src/ckan/ckan/tests/functional/test_user.py", line 342, in test_user_create_unicode
    res = res.follow()
  File "/usr/lib/pymodules/python2.6/paste/fixture.py", line 603, in follow
    return self.test_app.get(location, **kw)
  File "/usr/lib/pymodules/python2.6/paste/fixture.py", line 208, in get
    return self.do_request(req, status=status)
  File "/usr/lib/pymodules/python2.6/paste/fixture.py", line 389, in do_request
    **req.environ)
  File "/usr/lib/pymodules/python2.6/paste/wsgilib.py", line 343, in raw_interactive
    app_iter = application(basic_environ, start_response)
  File "/usr/lib/pymodules/python2.6/paste/lint.py", line 170, in lint_app
    iterator = application(environ, start_response_wrapper)
  File "/usr/lib/pymodules/python2.6/paste/cascade.py", line 130, in __call__
    return self.apps[-1](environ, start_response)
  File "/usr/lib/pymodules/python2.6/paste/registry.py", line 350, in __call__
    app_iter = self.application(environ, start_response)
  File "/usr/lib/pymodules/python2.6/repoze/who/middleware.py", line 69, in __call__
    auth_ids = self.authenticate(environ, classification, ids)
  File "/usr/lib/pymodules/python2.6/repoze/who/middleware.py", line 201, in authenticate
    userid = plugin.authenticate(environ, identity)
  File "/home/seanh/pyenv/src/ckan/ckan/lib/authenticator.py", line 29, in authenticate
    if user.validate_password(identity.get('password')):
  File "/home/seanh/pyenv/src/ckan/ckan/model/user.py", line 113, in validate_password
    hashed_pass = sha1(password_8bit + self.password[:40])
UnicodeDecodeError: 'ascii' codec can't decode byte 0xc3 in position 12: ordinal not in range(128)
&lt;/pre&gt;</description>
    <language>en-us</language>
    <image>
      <title>CKAN</title>
      <url>http://assets.okfn.org/p/ckan/img/ckan_logo_shortname.png</url>
      <link>http://localhost/ticket/1621</link>
    </image>
    <generator>Trac 0.12.3</generator>
    <item>
      
        <dc:creator>seanh</dc:creator>

      <pubDate>Mon, 09 Jan 2012 10:44:06 GMT</pubDate>
      <title>description changed</title>
      <link>http://localhost/ticket/1621#comment:1</link>
      <guid isPermaLink="false">http://localhost/ticket/1621#comment:1</guid>
      <description>
          &lt;ul&gt;
            &lt;li&gt;&lt;strong&gt;description&lt;/strong&gt;
              modified (&lt;a href="/ticket/1621?action=diff&amp;amp;version=1"&gt;diff&lt;/a&gt;)
            &lt;/li&gt;
          &lt;/ul&gt;
      </description>
      <category>Ticket</category>
    </item><item>
      
        <dc:creator>seanh</dc:creator>

      <pubDate>Tue, 01 May 2012 13:16:01 GMT</pubDate>
      <title>status changed; resolution set</title>
      <link>http://localhost/ticket/1621#comment:2</link>
      <guid isPermaLink="false">http://localhost/ticket/1621#comment:2</guid>
      <description>
          &lt;ul&gt;
            &lt;li&gt;&lt;strong&gt;status&lt;/strong&gt;
                changed from &lt;em&gt;new&lt;/em&gt; to &lt;em&gt;closed&lt;/em&gt;
            &lt;/li&gt;
            &lt;li&gt;&lt;strong&gt;resolution&lt;/strong&gt;
                set to &lt;em&gt;fixed&lt;/em&gt;
            &lt;/li&gt;
          &lt;/ul&gt;
        &lt;p&gt;
Closing because I haven't seen this test fail for ages
&lt;/p&gt;
      </description>
      <category>Ticket</category>
    </item>
 </channel>
</rss>