<?xml version="1.0"?>
<rss xmlns:dc="http://purl.org/dc/elements/1.1/" version="2.0">
  <channel>
    <title>CKAN: Ticket #2829: Archiver fails on 403 http response</title>
    <link>http://localhost/ticket/2829</link>
    <description>&lt;p&gt;
Had this issue with the archiver on my local machine need to be logged in (I am admin) to see via web front end
&lt;/p&gt;
&lt;pre class="wiki"&gt;$ paster archiver update -c ../ckan/development.ini
2012-08-09 11:01:37,636 INFO  [ckanext.archiver.commands] Archival of dataset resource data added to celery queue: opencontext-chogha-mish-fauna (1 resources)
2012-08-09 11:01:37,671 INFO  [ckanext.archiver.commands] Getting dataset metadata: south-african-national-gov-budget-2012-13
2012-08-09 11:01:37,900 INFO  [ckan.lib.base]  /api/action/package_show render time 0.043 seconds
Traceback (most recent call last):
  File "/home/toby/okfn/pyenv/bin/paster", line 8, in &amp;lt;module&amp;gt;
    load_entry_point('PasteScript==1.7.5', 'console_scripts', 'paster')()
  File "/home/toby/okfn/pyenv/lib/python2.7/site-packages/paste/script/command.py", line 104, in run
    invoke(command, command_name, options, args[1:])
  File "/home/toby/okfn/pyenv/lib/python2.7/site-packages/paste/script/command.py", line 143, in invoke
    exit_code = runner.run(args)
  File "/home/toby/okfn/pyenv/lib/python2.7/site-packages/paste/script/command.py", line 238, in run
    result = self.command()
  File "/home/toby/okfn/pyenv/src/ckanext-archiver/ckanext/archiver/commands.py", line 98, in command
    response = app.post(api_url + '/package_show', data)
  File "/home/toby/okfn/pyenv/lib/python2.7/site-packages/paste/fixture.py", line 262, in post
    expect_errors=expect_errors)
  File "/home/toby/okfn/pyenv/lib/python2.7/site-packages/paste/fixture.py", line 243, in _gen_request
    return self.do_request(req, status=status)
  File "/home/toby/okfn/pyenv/lib/python2.7/site-packages/paste/fixture.py", line 406, in do_request
    self._check_status(status, res)
  File "/home/toby/okfn/pyenv/lib/python2.7/site-packages/paste/fixture.py", line 439, in _check_status
    res.body))
paste.fixture.AppError: Bad response: 403 Forbidden (not 200 OK or 3xx redirect for /api/action/package_show)
{"help": "Return the metadata of a dataset (package) and its resources.\n\n    :param id: the id or name of the dataset\n    :type id: string\n\n    :rtype: dictionary\n\n    ", "success": false, "error": {"message": "Access denied", "__type": "Authorization Error"}}
&lt;/pre&gt;</description>
    <language>en-us</language>
    <image>
      <title>CKAN</title>
      <url>http://assets.okfn.org/p/ckan/img/ckan_logo_shortname.png</url>
      <link>http://localhost/ticket/2829</link>
    </image>
    <generator>Trac 0.12.3</generator>
 </channel>
</rss>